Traceback (most recent call last):
  File "/home/ise/jsonDL/preliminary_trials/env/cnn.py", line 323, in step_in_mode_train
    tf_info, _, tf_done = next(tf_phased_train)
  File "/home/ise/jsonDL/src/train_process/tf/phased_normal.py", line 61, in phased_normal_train
    train_step(model, x, y, train_loss, train_optim, loss_metric_train, metrics_dict_train)
  File "/home/ise/envs/tfpNewest/lib/python3.7/site-packages/tensorflow/python/util/traceback_utils.py", line 153, in error_handler
    raise e.with_traceback(filtered_tb) from None
  File "/home/ise/jsonDL/src/train_process/tf/phased_normal.py", line 97, in train_step
    loss_value = loss(y, predicts)
  File "/home/ise/envs/tfpNewest/lib/python3.7/site-packages/keras/losses.py", line 141, in __call__
    losses = call_fn(y_true, y_pred)
  File "/home/ise/envs/tfpNewest/lib/python3.7/site-packages/keras/losses.py", line 245, in call
    return ag_fn(y_true, y_pred, **self._fn_kwargs)
  File "/home/ise/envs/tfpNewest/lib/python3.7/site-packages/keras/losses.py", line 1665, in categorical_crossentropy
    y_true, y_pred, from_logits=from_logits, axis=axis)
  File "/home/ise/envs/tfpNewest/lib/python3.7/site-packages/keras/backend.py", line 4994, in categorical_crossentropy
    target.shape.assert_is_compatible_with(output.shape)
ValueError: Shapes (100, 10) and (1, 10) are incompatible
