Traceback (most recent call last):
  File "/home/ise/jsonDL/preliminary_trials/env/cnn.py", line 323, in step_in_mode_train
    tf_info, _, tf_done = next(tf_phased_train)
  File "/home/ise/jsonDL/src/train_process/tf/phased_normal.py", line 61, in phased_normal_train
    train_step(model, x, y, train_loss, train_optim, loss_metric_train, metrics_dict_train)
  File "/home/ise/envs/tfpNewest/lib/python3.7/site-packages/tensorflow/python/util/traceback_utils.py", line 153, in error_handler
    raise e.with_traceback(filtered_tb) from None
  File "/home/ise/jsonDL/src/train_process/tf/phased_normal.py", line 96, in train_step
    predicts = model(x, training=True)
  File "/home/ise/envs/tfpNewest/lib/python3.7/site-packages/keras/utils/traceback_utils.py", line 67, in error_handler
    raise e.with_traceback(filtered_tb) from None
  File "/home/ise/envs/tfpNewest/lib/python3.7/site-packages/keras/backend.py", line 5532, in conv2d_transpose
    data_format=tf_data_format)
tensorflow.python.framework.errors_impl.InvalidArgumentError: Exception encountered when calling layer "conv2d_transpose_1" (type Conv2DTranspose).

Conv2DCustomBackpropInput: Size of out_backprop doesn't match computed: actual = 32, computed = 31 spatial_dim: 1 input: 93 filter: 2 output: 32 stride: 3 dilation: 1 [Op:Conv2DBackpropInput]

Call arguments received:
  â€¢ inputs=tf.Tensor(shape=(100, 32, 32, 3), dtype=float32)
